<?xml version="1.0"?>
<robot name="aubo_i5" xmlns:xacro="http://ros.org/wiki/xacro">

 <!-- Defining the colors used in this robot -->
    <material name="Black">
        <color rgba="0 0 0 1"/>
    </material>

    <material name="White">
        <color rgba="1 1 1 1"/>
    </material>

    <material name="Blue">
        <color rgba="0 0 1 1"/>
    </material>

    <material name="Red">
        <color rgba="1 0 0 1"/>
    </material>

    <material name="Grey">
        <color rgba="0.96 0.96 0.96 1"/>
    </material>

    <!-- Constants -->
    <xacro:property name="M_PI" value="3.14159"/>







    <!--/////////////////// DYNAMICS PARAM //////////////////////-->

    <xacro:macro name="I5_Shoulder_Inertia">
        <origin xyz="0.0 0.006 -0.002"
                rpy="0 0 0" />
        <mass value="5.05" />
        <inertia ixx="0.0148"
                 ixy="0"
                 ixz="0"
                 iyy="0.0143"
                 iyz="-0.0"
                 izz="0.0095" />
    </xacro:macro>

    <xacro:macro name="I5_UpperArm_Inertia">
        <origin xyz="0.304 0.0 -0.03"
                rpy="0 0 0" />
        <mass value="11.90" />
        <inertia ixx="0.0305"
                 ixy="0"
                 ixz="0"
                 iyy="0.4505"
                 iyz="0"
                 izz="0.0095" />
    </xacro:macro>

    <xacro:macro name="I5_ForeArm_Inertia">
        <origin xyz="0.415 0.0 0.0992"
                rpy="0 0 0" />
        <mass  value="3.3" />
        <inertia ixx="0.0033"
                 ixy="0"
                 ixz="0.0009"
                 iyy="0.0575"
                 iyz="0"
                 izz="0.0565" />
    </xacro:macro>

    <xacro:macro name="I5_Wrist1_Inertia">
        <origin xyz="0.0 0.0028 -0.003"
                rpy="0 0 0" />
        <mass value="1.62" />
        <inertia ixx="0.0023"
                 ixy="0"
                 ixz="0"
                 iyy="0.0013"
                 iyz="0.0"
                 izz="0.0022" />
    </xacro:macro>

    <xacro:macro name="I5_Wrist2_Inertia">
        <origin xyz="0.0 -0.0028 -0.003"
                rpy="0 0 0" />
        <mass value="1.62" />
        <inertia ixx="0.0023"
                 ixy="0"
                 ixz="0"
                 iyy="0.0013"
                 iyz="0.0"
                 izz="0.0022" />
    </xacro:macro>

    <xacro:macro name="I5_Wrist3_Inertia">
        <origin xyz="0.0 0.0 -0.0071"
                rpy="0 0 0" />
        <mass value="0.40" />
        <inertia ixx="0.013939"
                 ixy="0"
                 ixz="0"
                 iyy="0.013988"
                 iyz="0.0"
                 izz="0.0224092" />
    </xacro:macro>

    <xacro:macro name="Knife_Inertia">
        <origin xyz="0 0 0" 
                rpy="0 0 0"/>        
        <mass value="2.900" />
        <inertia  ixx="9.262021396E-02"
                  ixy="4.23043326E-03"
                  ixz="5.458128035E-02"
                  iyy="1.3936975446E-01"
                  iyz="9.51563616E-03"
                  izz="6.341550849E-02" />
    </xacro:macro>

    <xacro:macro name="Camera_Inertia">
        <origin xyz="0 0 0"
                rpy="0 0 0"/>
        <mass value="0.564" />
        <inertia  ixx="0.003881243"
                  ixy="0.0"
                  ixz="0.0"
                  iyy="0.000498940"
                  iyz="0.0"
                  izz="0.003879257" />
    </xacro:macro>

    <xacro:macro name="Camera_Mount_Inertia">
        <origin xyz="0 0 0"
                rpy="0 0 0"/>
        <mass value="0.63617" />
        <inertia  ixx="2.57390373e-03"
                  ixy="0.4E-10"
                  ixz="-6.204366E-04"
                  iyy="2.87452369E-03"
                  iyz="-7.39E-09"
                  izz="5.2167513E-04" />
    </xacro:macro>

    <!--xacro:macro name="Charger_Inertia">
        <origin xyz="0 0 0"
                rpy="0 0 0"/>
        <mass value="0.564" />
        <inertia  ixx="0.003881243"
                  ixy="0.0"
                  ixz="0.0"
                  iyy="0.000498940"
                  iyz="0.0"
                  izz="0.003879257" />
    </xacro:macro-->



    <!--/////////////////////////////// BASE_LINK ////////////////////////////////////-->

   <link name="base_link">
    <inertial>
      <origin xyz="-1.4795E-13 0.0015384 0.020951" rpy="0 0 0" />
      <mass value="0.83419" />
      <inertia ixx="0.0014414" ixy="7.8809E-15" ixz="8.5328E-16" iyy="0.0013542" iyz="-1.4364E-05" izz="0.0024659" />
    </inertial>
    <visual>
      <origin xyz="0 0 0" rpy="0 0 0" />
      <geometry>
        <mesh filename="package://aubo_description/meshes/aubo_i5/visual/base_link.DAE" />
      </geometry>
      <material name="">
        <color rgba="1 1 1 1" />
      </material>
    </visual>
    <collision>
      <origin xyz="0 0 0" rpy="0 0 0" />
      <geometry>
        <mesh filename="package://aubo_description/meshes/aubo_i5/collision/base_link.STL" />
      </geometry>
    </collision>
  </link>


  <link name="velodyne">
    <visual>
      <origin xyz="0.0 0.0 0.0"/>
      <geometry>
        <cylinder length="0.07" radius="0.05" />
      </geometry>
      <material name="gray" />
    </visual>
  </link>

  <link name="imu_link">
    <visual>
      <origin xyz="0.0 0.0 0.0" />
      <geometry>
        <box size="0.04 0.02 0.01" />
      </geometry>
      <material name="orange" />
    </visual>
  </link>

  <joint name="imu_link_joint" type="fixed">
    <parent link="base_link" />
    <child link="imu_link" />
    <origin xyz="0. 0. 0." rpy="0 0 0" />
  </joint>

  <joint name="velodyne_joint" type="fixed">
    <parent link="base_link" />
    <child link="velodyne" />
    <origin xyz="0.32 0 0.035" rpy="0 0 0" />
  </joint>

  <!--/////////////////////////////// SHOULDER_LINK ////////////////////////////////////-->
  <link name="shoulder_Link">
    <inertial>
      <xacro:I5_Shoulder_Inertia />
    </inertial>
    <visual>
      <origin xyz="0 0 0" rpy="0 0 0" />
      <geometry>
        <mesh filename="package://aubo_description/meshes/aubo_i5/visual/shoulder_Link.DAE" />
      </geometry>
      <material name="">
        <color rgba="1 1 1 1" />
      </material>
    </visual>
    <collision>
      <origin xyz="0 0 0" rpy="0 0 0" />
      <geometry>
        <mesh filename="package://aubo_description/meshes/aubo_i5/collision/shoulder_Link.STL" />
      </geometry>
    </collision>
  </link>


  <!--/////////////////////////////// SHOULDER_JOINT ////////////////////////////////////-->
  <joint name="shoulder_joint" type="revolute">
    <origin xyz="0 0 0.122" rpy="0 0 3.1416" />
    <parent link="base_link" />
    <child link="shoulder_Link" />
    <axis xyz="0 0 1" />
    <limit lower="-3.05" upper="3.05" effort="300" velocity="100" />
  </joint>


  <!--/////////////////////////////// UPPERARM_LINK ////////////////////////////////////-->
  <link name="upperArm_Link">
    <inertial>
      <xacro:I5_UpperArm_Inertia />
    </inertial>
    <visual>
      <origin xyz="0 0 0" rpy="0 0 0" />
      <geometry>
        <mesh filename="package://aubo_description/meshes/aubo_i5/visual/upperArm_Link.DAE" />
      </geometry>
      <material name="">
        <color rgba="1 1 1 1" />
      </material>
    </visual>
    <collision>
      <origin xyz="0 0 0" rpy="0 0 0" />
      <geometry>
        <mesh filename="package://aubo_description/meshes/aubo_i5/collision/upperArm_Link.STL" />
      </geometry>
    </collision>
  </link>

  <!--/////////////////////////////// UPPERARM_JOINT ////////////////////////////////////-->
  <joint name="upperArm_joint" type="revolute">
    <origin xyz="0 0.1215 0" rpy="-1.5708 -1.5708 0" />
    <parent link="shoulder_Link" />
    <child link="upperArm_Link" />
    <axis xyz="0 0 1" />
    <limit lower="-3.05" upper="3.05" effort="300" velocity="100" />
  </joint>


  <!--/////////////////////////////// FOREARM_LINK ////////////////////////////////////-->
  <link name="foreArm_Link">
    <inertial>
      <xacro:I5_ForeArm_Inertia />
    </inertial>
    <visual>
      <origin xyz="0 0 0" rpy="0 0 0" />
      <geometry>
        <mesh filename="package://aubo_description/meshes/aubo_i5/visual/foreArm_Link.DAE" />
      </geometry>
      <material name="">
        <color rgba="1 1 1 1" />
      </material>
    </visual>
    <collision>
      <origin xyz="0 0 0" rpy="0 0 0" />
      <geometry>
        <mesh filename="package://aubo_description/meshes/aubo_i5/collision/foreArm_Link.STL" />
      </geometry>
    </collision>
  </link>


  <!--/////////////////////////////// FOREARM_JOINT ////////////////////////////////////-->
  <joint name="foreArm_joint" type="revolute">
    <origin xyz="0.408 0 0" rpy="-3.1416 -5.1632E-18 -5.459E-16" />
    <parent link="upperArm_Link" />
    <child link="foreArm_Link" />
    <axis xyz="0 0 1" />
    <limit lower="-3.05" upper="3.05" effort="300" velocity="100" />
  </joint>


  <!--/////////////////////////////// WRIST1_LINK ////////////////////////////////////-->
  <link name="wrist1_Link">
    <inertial>
      <xacro:I5_Wrist1_Inertia />
    </inertial>
    <visual>
      <origin xyz="0 0 0" rpy="0 0 0" />
      <geometry>
        <mesh filename="package://aubo_description/meshes/aubo_i5/visual/wrist1_Link.DAE" />
      </geometry>
      <material name="">
        <color rgba="1 1 1 1" />
      </material>
    </visual>
    <collision>
      <origin xyz="0 0 0" rpy="0 0 0" />
      <geometry>
        <mesh filename="package://aubo_description/meshes/aubo_i5/collision/wrist1_Link.STL" />
      </geometry>
    </collision>
  </link>


  <!--/////////////////////////////// WRIST1_JOINT ////////////////////////////////////-->
  <joint name="wrist1_joint" type="revolute">
    <origin xyz="0.376 0 0" rpy="3.1416 -1.8323E-15 1.5708" />
    <parent link="foreArm_Link" />
    <child link="wrist1_Link" />
    <axis xyz="0 0 1" />
    <limit lower="-3.05" upper="3.05" effort="300" velocity="100" />
  </joint>

  <!--/////////////////////////////// WRIST2_LINK ////////////////////////////////////-->
  <link name="wrist2_Link">
    <inertial>
      <xacro:I5_Wrist2_Inertia />
    </inertial>
    <visual>
      <origin xyz="0 0 0" rpy="0 0 0" />
      <geometry>
        <mesh filename="package://aubo_description/meshes/aubo_i5/visual/wrist2_Link.DAE" />
      </geometry>
      <material name="">
        <color rgba="1 1 1 1" />
      </material>
    </visual>
    <collision>
      <origin xyz="0 0 0" rpy="0 0 0" />
      <geometry>
        <mesh filename="package://aubo_description/meshes/aubo_i5/collision/wrist2_Link.STL" />
      </geometry>
    </collision>
  </link>

  <!--/////////////////////////////// WRIST2_JOINT ////////////////////////////////////-->
  <joint name="wrist2_joint" type="revolute">
    <origin xyz="0 0.1025 0" rpy="-1.5708 -1.8709E-15 -1.6653E-16" />
    <parent link="wrist1_Link" />
    <child link="wrist2_Link" />
    <axis xyz="0 0 1" />
    <limit lower="-3.05" upper="3.05" effort="300" velocity="100" />
  </joint>

  <!--/////////////////////////////// WRIST3_LINK ////////////////////////////////////-->
  <link name="wrist3_Link">
    <inertial>
      <xacro:I5_Wrist3_Inertia />
    </inertial>
    <visual>
      <origin xyz="0 0 0" rpy="0 0 0" />
      <geometry>
        <mesh filename="package://aubo_description/meshes/aubo_i5/visual/wrist3_Link.DAE" />
      </geometry>
      <material name="">
        <color rgba="1 1 1 1" />
      </material>
    </visual>
    <collision>
      <origin xyz="0 0 0" rpy="0 0 0" />
      <geometry>
        <mesh filename="package://aubo_description/meshes/aubo_i5/collision/wrist3_Link.STL" />
      </geometry>
    </collision>
  </link>

  <!--/////////////////////////////// WRIST3_JOINT ////////////////////////////////////-->
  <joint name="wrist3_joint" type="revolute">
    <origin xyz="0 -0.094 0" rpy="1.5708 0 1.7907E-15" />
    <parent link="wrist2_Link" />
    <child link="wrist3_Link" />
    <axis xyz="0 0 1" />
    <limit lower="-3.05" upper="3.05" effort="300" velocity="100" />
  </joint>
  <!--////////////////////////////////CameraMount_Link/////////////////////////////////-->
  <link name="knife_link" >
    <visual>
      <origin xyz="0.0 0.0 0.0" rpy="0 0 0"/>
      <geometry>
         <mesh filename="package://aubo_description/meshes/knife.STL" />
      </geometry>
      <!--material name="aluminum"/-->
    </visual>
    <collision>
      <origin xyz="0.0 0.0 0.0" rpy="0 0 0"/>
      <geometry>
         <mesh filename="package://aubo_description/meshes/knife.STL" />
      </geometry>
    </collision>
    <inertial>
      <xacro:Knife_Inertia />
    </inertial>
  </link>
  <!--////////////////////////////////CameraMount_Joint/////////////////////////////////-->
  <joint name="knife_mount_joint" type="fixed">
    <origin xyz="0.0 0.0 0.00575" rpy="1.5707 0.0 3.1415"/>
    <parent link="wrist3_Link"/>
    <child link="knife_link"/>
  </joint>
  <!--////////////////////////////////CameraMount_Link/////////////////////////////////-->
  <link name="camera_mount_link" >
    <visual>
      <origin xyz="0.0 0.0 0.0" rpy="0 0 0"/>
      <geometry>
         <mesh filename="package://aubo_description/meshes/CameraMountBoard.dae" />
      </geometry>
      <material name="aluminum"/>
    </visual>
    <collision>
      <origin xyz="0.0 0.0 0.0" rpy="0 0 0"/>
      <geometry>
         <mesh filename="package://aubo_description/meshes/CameraMountBoard.stl" />
      </geometry>
    </collision>
    <inertial>
      <xacro:Camera_Mount_Inertia />
    </inertial>
  </link>
  <!--////////////////////////////////CameraMount_Joint/////////////////////////////////-->
  <joint name="knife_camera_mount_joint" type="fixed">
    <origin xyz="0.0 0.0 0.0001" rpy="0.00 0.0 0.0277"/>
    <parent link="wrist3_Link"/>
    <child link="camera_mount_link"/>
  </joint>

  <!--////////////////////////////////camera/////////////////////////////////-->
  <link name="camera_link">
    <collision>
        <origin xyz="0.001 -0.0175 0" rpy="0 0 0"/>
        <geometry>
        <box size="0.02505 0.090 0.025"/>

        </geometry>
      </collision>
    <visual>
      <origin xyz="0.0149 -0.0175 0" rpy="1.5707 0 1.5707"/>
      <geometry>
         <mesh filename="package://aubo_description/meshes/d435.dae" />
      </geometry>
      <material name="aluminum"/>
    </visual>

     <inertial>
        <xacro:Camera_Inertia />
      </inertial>
  </link>
  <!--////////////////////////////////camera_joint/////////////////////////////////-->
  <joint name="camera_joint" type="fixed">
    <origin xyz="0.03358 0.098 -0.05518" rpy="-1.5707 -1.5707 0"/>
    <parent link="camera_mount_link"/>
    <child link="camera_link"/>
  </joint>
  <!--////////////////////////////////charger/////////////////////////////////-->
  <!--link name="charger_link">
    <collision>
      <origin xyz="0.0 0.0 0.0" rpy="0 0 0"/>
      <geometry>
         <mesh filename="package://aubo_description/meshes/charger.stl" />
      </geometry>
    </collision>
    <visual>
      <origin xyz="0.0 0.0 0.0" rpy="0.0 0.0 0.0"/>
      <geometry>
         <mesh filename="package://aubo_description/meshes/charger.dae" />
      </geometry>
      <material name="aluminum"/>
    </visual>
    <inertial>
      <xacro:Charger_Inertia />
    </inertial>
  </link-->

  <!--////////////////////////////////knife_charger_joint/////////////////////////////////-->
  <!--joint name="knife_charger_joint" type="fixed">
    <origin xyz="0.065 -0.08975 0.060" rpy="0.0 0.0 0.0"/>
    <parent link="camera_mount_link"/>
    <child link="charger_link"/>
  </joint-->
    <!--0.0149 0.047621 0.110-->


 <!-- /////////////////////////////////   world   ////////////////////////////////////// -->
  <link name="ee_link"/>

  <joint name="ee_link_joint" type="fixed">
      <origin xyz="0.0 0.0 0.2" rpy="-1.5707 0.0 0.0"/>
      <parent link="wrist3_Link"/>
      <child link="ee_link" />
  </joint>

  <!--link name="charger_ee_link"/-->

  <!--joint name="charger_ee_link_joint" type="fixed">
      <origin xyz="0.053 0.0 0.0" rpy="${-M_PI/2} 0.0 0.0"/>
      <parent link="charger_link"/>
      <child link="charger_ee_link" />
  </joint-->
  
  <link name="virtual_camera_color_frame" />
  <joint name="virtual_camera_joint" type="fixed">
    <parent link="camera_link" />
    <child link = "virtual_camera_color_frame" />
    <origin xyz="-0.000 0.015 0.000" rpy="-0.007 0.002 0.009" />
  </joint>

  <!-- /////////////////////////////////   gazebo color   ////////////////////////////////////// -->
  <gazebo reference="camera_mount_link">
     <material>Gazebo/White</material>
  </gazebo>
  <gazebo reference="camera_link">
     <material>Gazebo/Gray</material>
  </gazebo>
   <!--gazebo reference="charger_link">
     <material>Gazebo/Orange</material>
  </gazebo-->

  <!--////////////////////////////////// Transmissions for ROS Control //////////////////////////-->

<xacro:macro name="aubo_arm_transmission" params="joint_name">
     <transmission name="${joint_name}_trans">
       <type>transmission_interface/SimpleTransmission</type>
       <joint name="${joint_name}">
         <!--<hardwareInterface>hardware_interface/PositionJointInterface</hardwareInterface>-->
         <hardwareInterface>hardware_interface/PositionJointInterface</hardwareInterface>
       </joint>
       <actuator name="${joint_name}_motor">
         <mechanicalReduction>1</mechanicalReduction>
       </actuator>
     </transmission>
 </xacro:macro>


  <xacro:aubo_arm_transmission joint_name="shoulder_joint"/>
  <xacro:aubo_arm_transmission joint_name="upperArm_joint"/>
  <xacro:aubo_arm_transmission joint_name="foreArm_joint"/>
  <xacro:aubo_arm_transmission joint_name="wrist1_joint"/>
  <xacro:aubo_arm_transmission joint_name="wrist2_joint"/>
  <xacro:aubo_arm_transmission joint_name="wrist3_joint"/>




  <!-- ros_control plugin -->
  <gazebo>
      <plugin name="gazebo_ros_control" filename="libgazebo_ros_control.so">
          <robotNamespace>/aubo_i5</robotNamespace>
          <robotSimType>gazebo_ros_control/DefaultRobotHWSim</robotSimType>
          <legacyModeNS>true</legacyModeNS>
      </plugin>
  </gazebo>

  <gazebo reference="virtual_camera_color_frame">
    <sensor type="camera" name="camera1">
      <update_rate>30.0</update_rate>
      <camera name="realsense">
        <horizontal_fov>1.047</horizontal_fov>
        <image>
          <width>640</width>
          <height>480</height>
          <format>RGB_INT8</format>
        </image>
        <clip>
          <near>0.1</near>
          <far>100</far>
        </clip>
        <noise>
          <type>gaussian</type>
          <!-- Noise is sampled independently per pixel on each frame.
               That pixel's noise value is added to each of its color
               channels, which at that point lie in the range [0,1]. -->
          <mean>0.0</mean>
          <stddev>0.007</stddev>
        </noise>
      </camera>
      <plugin name="camera_controller" filename="libgazebo_ros_camera.so">
        <alwaysOn>true</alwaysOn>
        <updateRate>30.0</updateRate>
        <cameraName>camera/color</cameraName>
        <imageTopicName>image_raw</imageTopicName>
        <cameraInfoTopicName>camera_info</cameraInfoTopicName>
        <frameName>camera_color_optical_frame</frameName>
        <distortionK1>0.0</distortionK1>
        <distortionK2>0.0</distortionK2>
        <distortionK3>0.0</distortionK3>
        <distortionT1>0.0</distortionT1>
        <distortionT2>0.0</distortionT2>
        <CxPrime>0.0</CxPrime>
        <Cx>324.5312805175781</Cx>
        <Cy>236.61178588867188</Cy>
      </plugin>
    </sensor>
  </gazebo>


</robot>
