<sdf version='1.6'>
  <world name='default'>
    <light name='sun' type='directional'>
      <cast_shadows>1</cast_shadows>
      <pose frame=''>0 0 10 0 -0 0</pose>
      <diffuse>0.8 0.8 0.8 1</diffuse>
      <specular>0.2 0.2 0.2 1</specular>
      <attenuation>
        <range>1000</range>
        <constant>0.9</constant>
        <linear>0.01</linear>
        <quadratic>0.001</quadratic>
      </attenuation>
      <direction>-0.5 0.1 -0.9</direction>
    </light>
    <model name='ground_plane'>
      <static>1</static>
      <link name='link'>
        <collision name='collision'>
          <geometry>
            <plane>
              <normal>0 0 1</normal>
              <size>100 100</size>
            </plane>
          </geometry>
          <surface>
            <friction>
              <ode>
                <mu>100</mu>
                <mu2>50</mu2>
              </ode>
              <torsional>
                <ode/>
              </torsional>
            </friction>
            <contact>
              <ode/>
            </contact>
            <bounce/>
          </surface>
          <max_contacts>10</max_contacts>
        </collision>
        <visual name='visual'>
          <cast_shadows>0</cast_shadows>
          <geometry>
            <plane>
              <normal>0 0 1</normal>
              <size>100 100</size>
            </plane>
          </geometry>
          <material>
            <script>
              <uri>file://media/materials/scripts/gazebo.material</uri>
              <name>Gazebo/Grey</name>
            </script>
          </material>
        </visual>
        <self_collide>0</self_collide>
        <enable_wind>0</enable_wind>
        <kinematic>0</kinematic>
      </link>
    </model>
    <gravity>0 0 -9.8</gravity>
    <magnetic_field>6e-06 2.3e-05 -4.2e-05</magnetic_field>
    <atmosphere type='adiabatic'/>
    <physics name='default_physics' default='0' type='ode'>
      <max_step_size>0.001</max_step_size>
      <real_time_factor>1</real_time_factor>
      <real_time_update_rate>1000</real_time_update_rate>
    </physics>
    <scene>
      <ambient>0.4 0.4 0.4 1</ambient>
      <background>0.7 0.7 0.7 1</background>
      <shadows>1</shadows>
    </scene>
    <wind/>
    <spherical_coordinates>
      <surface_model>EARTH_WGS84</surface_model>
      <latitude_deg>0</latitude_deg>
      <longitude_deg>0</longitude_deg>
      <elevation>0</elevation>
      <heading_deg>0</heading_deg>
    </spherical_coordinates>
    <model name='arm'>
      <link name='base_link'>
        <pose frame=''>0 0 0 0 -0 0</pose>
        <inertial>
          <pose frame=''>-0 0.001538 0.020951 0 -0 0</pose>
          <mass>0.83419</mass>
          <inertia>
            <ixx>0.0014414</ixx>
            <ixy>7.8809e-15</ixy>
            <ixz>8.5328e-16</ixz>
            <iyy>0.0013542</iyy>
            <iyz>-1.4364e-05</iyz>
            <izz>0.0024659</izz>
          </inertia>
        </inertial>
        <collision name='base_link_collision'>
          <pose frame=''>0 0 0 0 -0 0</pose>
          <geometry>
            <mesh>
              <scale>1 1 1</scale>
              <uri>/home/xcy/WorkSpace/src/aubo_robot_realsense/aubo_description/meshes/aubo_i5/collision/base_link.STL</uri>
            </mesh>
          </geometry>
          <max_contacts>10</max_contacts>
          <surface>
            <contact>
              <ode/>
            </contact>
            <bounce/>
            <friction>
              <torsional>
                <ode/>
              </torsional>
              <ode/>
            </friction>
          </surface>
        </collision>
        <visual name='base_link_visual'>
          <pose frame=''>0 0 0 0 -0 0</pose>
          <geometry>
            <mesh>
              <scale>1 1 1</scale>
              <uri>/home/xcy/WorkSpace/src/aubo_robot_realsense/aubo_description/meshes/aubo_i5/visual/base_link.DAE</uri>
            </mesh>
          </geometry>
        </visual>
        <self_collide>0</self_collide>
        <enable_wind>0</enable_wind>
        <kinematic>0</kinematic>
      </link>
      <joint name='world_joint' type='fixed'>
        <child>base_link</child>
        <parent>world</parent>
      </joint>
      <link name='shoulder_Link'>
        <pose frame=''>0 0 0.122 0 -0 -3.14159</pose>
        <inertial>
          <pose frame=''>0 0.006 -0.002 0 -0 0</pose>
          <mass>5.05</mass>
          <inertia>
            <ixx>0.0148</ixx>
            <ixy>0</ixy>
            <ixz>0</ixz>
            <iyy>0.0143</iyy>
            <iyz>-0</iyz>
            <izz>0.0095</izz>
          </inertia>
        </inertial>
        <collision name='shoulder_Link_collision'>
          <pose frame=''>0 0 0 0 -0 0</pose>
          <geometry>
            <mesh>
              <scale>1 1 1</scale>
              <uri>/home/xcy/WorkSpace/src/aubo_robot_realsense/aubo_description/meshes/aubo_i5/collision/shoulder_Link.STL</uri>
            </mesh>
          </geometry>
          <max_contacts>10</max_contacts>
          <surface>
            <contact>
              <ode/>
            </contact>
            <bounce/>
            <friction>
              <torsional>
                <ode/>
              </torsional>
              <ode/>
            </friction>
          </surface>
        </collision>
        <visual name='shoulder_Link_visual'>
          <pose frame=''>0 0 0 0 -0 0</pose>
          <geometry>
            <mesh>
              <scale>1 1 1</scale>
              <uri>/home/xcy/WorkSpace/src/aubo_robot_realsense/aubo_description/meshes/aubo_i5/visual/shoulder_Link.DAE</uri>
            </mesh>
          </geometry>
        </visual>
        <self_collide>0</self_collide>
        <enable_wind>0</enable_wind>
        <kinematic>0</kinematic>
      </link>
      <joint name='shoulder_joint' type='revolute'>
        <child>shoulder_Link</child>
        <parent>base_link</parent>
        <axis>
          <xyz>0 0 1</xyz>
          <limit>
            <lower>-3.05</lower>
            <upper>3.05</upper>
            <effort>300</effort>
            <velocity>100</velocity>
          </limit>
          <dynamics>
            <spring_reference>0</spring_reference>
            <spring_stiffness>0</spring_stiffness>
          </dynamics>
          <use_parent_model_frame>1</use_parent_model_frame>
        </axis>
      </joint>
      <link name='upperArm_Link'>
        <pose frame=''>1e-06 -0.1215 0.122 1.57079 -1.57079 7e-06</pose>
        <inertial>
          <pose frame=''>0.304 0 -0.03 0 -0 0</pose>
          <mass>11.9</mass>
          <inertia>
            <ixx>0.0305</ixx>
            <ixy>0</ixy>
            <ixz>0</ixz>
            <iyy>0.4505</iyy>
            <iyz>0</iyz>
            <izz>0.0095</izz>
          </inertia>
        </inertial>
        <collision name='upperArm_Link_collision'>
          <pose frame=''>0 0 0 0 -0 0</pose>
          <geometry>
            <mesh>
              <scale>1 1 1</scale>
              <uri>/home/xcy/WorkSpace/src/aubo_robot_realsense/aubo_description/meshes/aubo_i5/collision/upperArm_Link.STL</uri>
            </mesh>
          </geometry>
          <max_contacts>10</max_contacts>
          <surface>
            <contact>
              <ode/>
            </contact>
            <bounce/>
            <friction>
              <torsional>
                <ode/>
              </torsional>
              <ode/>
            </friction>
          </surface>
        </collision>
        <visual name='upperArm_Link_visual'>
          <pose frame=''>0 0 0 0 -0 0</pose>
          <geometry>
            <mesh>
              <scale>1 1 1</scale>
              <uri>/home/xcy/WorkSpace/src/aubo_robot_realsense/aubo_description/meshes/aubo_i5/visual/upperArm_Link.DAE</uri>
            </mesh>
          </geometry>
        </visual>
        <self_collide>0</self_collide>
        <enable_wind>0</enable_wind>
        <kinematic>0</kinematic>
      </link>
      <joint name='upperArm_joint' type='revolute'>
        <child>upperArm_Link</child>
        <parent>shoulder_Link</parent>
        <axis>
          <xyz>4e-06 -1 0</xyz>
          <limit>
            <lower>-3.05</lower>
            <upper>3.05</upper>
            <effort>300</effort>
            <velocity>100</velocity>
          </limit>
          <dynamics>
            <spring_reference>0</spring_reference>
            <spring_stiffness>0</spring_stiffness>
          </dynamics>
          <use_parent_model_frame>1</use_parent_model_frame>
        </axis>
      </joint>
      <link name='foreArm_Link'>
        <pose frame=''>2e-06 -0.1215 0.53 -1.57081 -1.57079 7e-06</pose>
        <inertial>
          <pose frame=''>0.415 0 0.0992 0 -0 0</pose>
          <mass>3.3</mass>
          <inertia>
            <ixx>0.0033</ixx>
            <ixy>0</ixy>
            <ixz>0.0009</ixz>
            <iyy>0.0575</iyy>
            <iyz>0</iyz>
            <izz>0.0565</izz>
          </inertia>
        </inertial>
        <collision name='foreArm_Link_collision'>
          <pose frame=''>0 0 0 0 -0 0</pose>
          <geometry>
            <mesh>
              <scale>1 1 1</scale>
              <uri>/home/xcy/WorkSpace/src/aubo_robot_realsense/aubo_description/meshes/aubo_i5/collision/foreArm_Link.STL</uri>
            </mesh>
          </geometry>
          <max_contacts>10</max_contacts>
          <surface>
            <contact>
              <ode/>
            </contact>
            <bounce/>
            <friction>
              <torsional>
                <ode/>
              </torsional>
              <ode/>
            </friction>
          </surface>
        </collision>
        <visual name='foreArm_Link_visual'>
          <pose frame=''>0 0 0 0 -0 0</pose>
          <geometry>
            <mesh>
              <scale>1 1 1</scale>
              <uri>/home/xcy/WorkSpace/src/aubo_robot_realsense/aubo_description/meshes/aubo_i5/visual/foreArm_Link.DAE</uri>
            </mesh>
          </geometry>
        </visual>
        <self_collide>0</self_collide>
        <enable_wind>0</enable_wind>
        <kinematic>0</kinematic>
      </link>
      <joint name='foreArm_joint' type='revolute'>
        <child>foreArm_Link</child>
        <parent>upperArm_Link</parent>
        <axis>
          <xyz>4e-06 1 -0</xyz>
          <limit>
            <lower>-3.05</lower>
            <upper>3.05</upper>
            <effort>300</effort>
            <velocity>100</velocity>
          </limit>
          <dynamics>
            <spring_reference>0</spring_reference>
            <spring_stiffness>0</spring_stiffness>
          </dynamics>
          <use_parent_model_frame>1</use_parent_model_frame>
        </axis>
      </joint>
      <link name='wrist1_Link'>
        <pose frame=''>4e-06 -0.1215 0.906 1.5708 7e-06 -4e-06</pose>
        <inertial>
          <pose frame=''>0 0.0028 -0.003 0 -0 0</pose>
          <mass>1.62</mass>
          <inertia>
            <ixx>0.0023</ixx>
            <ixy>0</ixy>
            <ixz>0</ixz>
            <iyy>0.0013</iyy>
            <iyz>0</iyz>
            <izz>0.0022</izz>
          </inertia>
        </inertial>
        <collision name='wrist1_Link_collision'>
          <pose frame=''>0 0 0 0 -0 0</pose>
          <geometry>
            <mesh>
              <scale>1 1 1</scale>
              <uri>/home/xcy/WorkSpace/src/aubo_robot_realsense/aubo_description/meshes/aubo_i5/collision/wrist1_Link.STL</uri>
            </mesh>
          </geometry>
          <max_contacts>10</max_contacts>
          <surface>
            <contact>
              <ode/>
            </contact>
            <bounce/>
            <friction>
              <torsional>
                <ode/>
              </torsional>
              <ode/>
            </friction>
          </surface>
        </collision>
        <visual name='wrist1_Link_visual'>
          <pose frame=''>0 0 0 0 -0 0</pose>
          <geometry>
            <mesh>
              <scale>1 1 1</scale>
              <uri>/home/xcy/WorkSpace/src/aubo_robot_realsense/aubo_description/meshes/aubo_i5/visual/wrist1_Link.DAE</uri>
            </mesh>
          </geometry>
        </visual>
        <self_collide>0</self_collide>
        <enable_wind>0</enable_wind>
        <kinematic>0</kinematic>
      </link>
      <joint name='wrist1_joint' type='revolute'>
        <child>wrist1_Link</child>
        <parent>foreArm_Link</parent>
        <axis>
          <xyz>-4e-06 -1 -7e-06</xyz>
          <limit>
            <lower>-3.05</lower>
            <upper>3.05</upper>
            <effort>300</effort>
            <velocity>100</velocity>
          </limit>
          <dynamics>
            <spring_reference>0</spring_reference>
            <spring_stiffness>0</spring_stiffness>
          </dynamics>
          <use_parent_model_frame>1</use_parent_model_frame>
        </axis>
      </joint>
      <link name='wrist2_Link'>
        <pose frame=''>5e-06 -0.121501 1.0085 4e-06 7e-06 -4e-06</pose>
        <inertial>
          <pose frame=''>0 -0.0028 -0.003 0 -0 0</pose>
          <mass>1.62</mass>
          <inertia>
            <ixx>0.0023</ixx>
            <ixy>0</ixy>
            <ixz>0</ixz>
            <iyy>0.0013</iyy>
            <iyz>0</iyz>
            <izz>0.0022</izz>
          </inertia>
        </inertial>
        <collision name='wrist2_Link_collision'>
          <pose frame=''>0 0 0 0 -0 0</pose>
          <geometry>
            <mesh>
              <scale>1 1 1</scale>
              <uri>/home/xcy/WorkSpace/src/aubo_robot_realsense/aubo_description/meshes/aubo_i5/collision/wrist2_Link.STL</uri>
            </mesh>
          </geometry>
          <max_contacts>10</max_contacts>
          <surface>
            <contact>
              <ode/>
            </contact>
            <bounce/>
            <friction>
              <torsional>
                <ode/>
              </torsional>
              <ode/>
            </friction>
          </surface>
        </collision>
        <visual name='wrist2_Link_visual'>
          <pose frame=''>0 0 0 0 -0 0</pose>
          <geometry>
            <mesh>
              <scale>1 1 1</scale>
              <uri>/home/xcy/WorkSpace/src/aubo_robot_realsense/aubo_description/meshes/aubo_i5/visual/wrist2_Link.DAE</uri>
            </mesh>
          </geometry>
        </visual>
        <self_collide>0</self_collide>
        <enable_wind>0</enable_wind>
        <kinematic>0</kinematic>
      </link>
      <joint name='wrist2_joint' type='revolute'>
        <child>wrist2_Link</child>
        <parent>wrist1_Link</parent>
        <axis>
          <xyz>7e-06 -4e-06 1</xyz>
          <limit>
            <lower>-3.05</lower>
            <upper>3.05</upper>
            <effort>300</effort>
            <velocity>100</velocity>
          </limit>
          <dynamics>
            <spring_reference>0</spring_reference>
            <spring_stiffness>0</spring_stiffness>
          </dynamics>
          <use_parent_model_frame>1</use_parent_model_frame>
        </axis>
      </joint>
      <link name='wrist3_Link'>
        <pose frame=''>4e-06 -0.215501 1.0085 1.5708 7e-06 -4e-06</pose>
        <inertial>
          <pose frame=''>0.028868 0.053662 0.033774 0 -0 0</pose>
          <mass>1.561</mass>
          <inertia>
            <ixx>0.0237953</ixx>
            <ixy>0.000492011</ixy>
            <ixz>-0.00135887</ixz>
            <iyy>0.0211633</iyy>
            <iyz>8.70115e-05</iyz>
            <izz>0.0352632</izz>
          </inertia>
        </inertial>
        <collision name='wrist3_Link_collision'>
          <pose frame=''>0 0 0 0 -0 0</pose>
          <geometry>
            <mesh>
              <scale>1 1 1</scale>
              <uri>/home/xcy/WorkSpace/src/aubo_robot_realsense/aubo_description/meshes/aubo_i5/collision/wrist3_Link.STL</uri>
            </mesh>
          </geometry>
          <max_contacts>10</max_contacts>
          <surface>
            <contact>
              <ode/>
            </contact>
            <bounce/>
            <friction>
              <torsional>
                <ode/>
              </torsional>
              <ode/>
            </friction>
          </surface>
        </collision>
        <collision name='wrist3_Link_fixed_joint_lump__camera_mount_link_collision_1'>
          <pose frame=''>0 0.11575 0.01288 0 -0 0</pose>
          <geometry>
            <mesh>
              <scale>1 1 1</scale>
              <uri>/home/xcy/WorkSpace/src/aubo_robot_realsense/aubo_description/meshes/CameraMountBoard.stl</uri>
            </mesh>
          </geometry>
          <surface>
            <contact>
              <ode/>
            </contact>
            <friction>
              <ode/>
              <torsional>
                <ode/>
              </torsional>
            </friction>
            <bounce/>
          </surface>
          <max_contacts>10</max_contacts>
        </collision>
        <collision name='wrist3_Link_fixed_joint_lump__camera_link_collision_2'>
          <pose frame=''>-0.0026 0.115748 0.02588 3.14159 -1.57079 1.57089</pose>
          <geometry>
            <box>
              <size>0.02505 0.09 0.025</size>
            </box>
          </geometry>
          <surface>
            <contact>
              <ode/>
            </contact>
            <friction>
              <ode/>
              <torsional>
                <ode/>
              </torsional>
            </friction>
            <bounce/>
          </surface>
          <max_contacts>10</max_contacts>
        </collision>
        <collision name='wrist3_Link_fixed_joint_lump__charger_link_collision_3'>
          <pose frame=''>0.065 0.026 0.07288 0 -0 0</pose>
          <geometry>
            <mesh>
              <scale>1 1 1</scale>
              <uri>/home/xcy/WorkSpace/src/aubo_robot_realsense/aubo_description/meshes/charger.stl</uri>
            </mesh>
          </geometry>
          <surface>
            <contact>
              <ode/>
            </contact>
            <friction>
              <ode/>
              <torsional>
                <ode/>
              </torsional>
            </friction>
            <bounce/>
          </surface>
          <max_contacts>10</max_contacts>
        </collision>
        <visual name='wrist3_Link_visual'>
          <pose frame=''>0 0 0 0 -0 0</pose>
          <geometry>
            <mesh>
              <scale>1 1 1</scale>
              <uri>/home/xcy/WorkSpace/src/aubo_robot_realsense/aubo_description/meshes/aubo_i5/visual/wrist3_Link.DAE</uri>
            </mesh>
          </geometry>
        </visual>
        <visual name='wrist3_Link_fixed_joint_lump__camera_mount_link_visual_1'>
          <pose frame=''>0 0.11575 0.01288 0 -0 0</pose>
          <geometry>
            <mesh>
              <scale>1 1 1</scale>
              <uri>/home/xcy/WorkSpace/src/aubo_robot_realsense/aubo_description/meshes/CameraMountBoard.dae</uri>
            </mesh>
          </geometry>
          <material>
            <script>
              <name>Gazebo/White</name>
              <uri>file://media/materials/scripts/gazebo.material</uri>
            </script>
          </material>
        </visual>
        <visual name='wrist3_Link_fixed_joint_lump__camera_link_visual_2'>
          <pose frame=''>-0.0026 0.115747 0.03978 0 -9.6e-05 9.6e-05</pose>
          <geometry>
            <mesh>
              <scale>1 1 1</scale>
              <uri>/home/xcy/WorkSpace/src/aubo_robot_realsense/aubo_description/meshes/d435.dae</uri>
            </mesh>
          </geometry>
          <material>
            <script>
              <name>Gazebo/Gray</name>
              <uri>file://media/materials/scripts/gazebo.material</uri>
            </script>
          </material>
        </visual>
        <visual name='wrist3_Link_fixed_joint_lump__charger_link_visual_3'>
          <pose frame=''>0.065 0.026 0.07288 0 -0 0</pose>
          <geometry>
            <mesh>
              <scale>1 1 1</scale>
              <uri>/home/xcy/WorkSpace/src/aubo_robot_realsense/aubo_description/meshes/charger.dae</uri>
            </mesh>
          </geometry>
          <material>
            <script>
              <name>Gazebo/Orange</name>
              <uri>file://media/materials/scripts/gazebo.material</uri>
            </script>
          </material>
        </visual>
        <velocity_decay/>
        <velocity_decay/>
        <velocity_decay/>
        <sensor name='camera1' type='camera'>
          <update_rate>30</update_rate>
          <camera name='realsense'>
            <horizontal_fov>1.047</horizontal_fov>
            <image>
              <width>640</width>
              <height>480</height>
              <format>RGB_INT8</format>
            </image>
            <clip>
              <near>0.1</near>
              <far>100</far>
            </clip>
            <noise>
              <type>gaussian</type>
              <mean>0</mean>
              <stddev>0.007</stddev>
            </noise>
          </camera>
          <plugin name='camera_controller' filename='libgazebo_ros_camera.so'>
            <alwaysOn>1</alwaysOn>
            <updateRate>30.0</updateRate>
            <cameraName>camera/color</cameraName>
            <imageTopicName>image_raw</imageTopicName>
            <cameraInfoTopicName>camera_info</cameraInfoTopicName>
            <frameName>camera_color_optical_frame</frameName>
            <distortionK1>0.0</distortionK1>
            <distortionK2>0.0</distortionK2>
            <distortionK3>0.0</distortionK3>
            <distortionT1>0.0</distortionT1>
            <distortionT2>0.0</distortionT2>
            <CxPrime>0.0</CxPrime>
            <Cx>324.5312805175781</Cx>
            <Cy>236.61178588867188</Cy>
            <robotNamespace>/</robotNamespace>
          </plugin>
          <pose frame=''>0.0299 0.115751 0.02488 -1.34896 -1.56156 -0.228751</pose>
        </sensor>
        <gravity>1</gravity>
        <velocity_decay/>
        <self_collide>0</self_collide>
        <enable_wind>0</enable_wind>
        <kinematic>0</kinematic>
      </link>
      <joint name='wrist3_joint' type='revolute'>
        <child>wrist3_Link</child>
        <parent>wrist2_Link</parent>
        <axis>
          <xyz>-4e-06 -1 -7e-06</xyz>
          <limit>
            <lower>-3.05</lower>
            <upper>3.05</upper>
            <effort>300</effort>
            <velocity>100</velocity>
          </limit>
          <dynamics>
            <spring_reference>0</spring_reference>
            <spring_stiffness>0</spring_stiffness>
          </dynamics>
          <use_parent_model_frame>1</use_parent_model_frame>
        </axis>
      </joint>
      <static>0</static>
      <plugin name='gazebo_ros_control' filename='libgazebo_ros_control.so'>
        <robotNamespace>/aubo_i5</robotNamespace>
        <robotSimType>gazebo_ros_control/DefaultRobotHWSim</robotSimType>
        <legacyModeNS>1</legacyModeNS>
      </plugin>
      <pose frame=''>0 0 0 0 -0 0</pose>
    </model>
    <model name='Heava'>
      <static>1</static>
      <pose frame=''>0.000876 -1.0055 0 0 -0 0</pose>
      <link name='cylinder'>
        <pose frame=''>0 0 0 0 -0 0</pose>
        <collision name='collision'>
          <geometry>
            <cylinder>
              <radius>0.1</radius>
              <length>5</length>
            </cylinder>
          </geometry>
          <max_contacts>10</max_contacts>
          <surface>
            <contact>
              <ode/>
            </contact>
            <bounce/>
            <friction>
              <torsional>
                <ode/>
              </torsional>
              <ode/>
            </friction>
          </surface>
        </collision>
        <visual name='visual'>
          <geometry>
            <cylinder>
              <radius>0.1</radius>
              <length>5</length>
            </cylinder>
          </geometry>
          <material>
            <script>
              <uri>model://Heava/materials/scripts</uri>
              <uri>model://Heava/materials/textures</uri>
              <name>Heava/skin</name>
            </script>
          </material>
        </visual>
        <self_collide>0</self_collide>
        <enable_wind>0</enable_wind>
        <kinematic>0</kinematic>
      </link>
    </model>
    <model name='Tag0'>
      <static>1</static>
      <link name='link'>
        <pose frame=''>0 0 0.1 0 -0 0</pose>
        <collision name='collision'>
          <geometry>
            <box>
              <size>0.1 0.001 0.1</size>
            </box>
          </geometry>
          <max_contacts>10</max_contacts>
          <surface>
            <contact>
              <ode/>
            </contact>
            <bounce/>
            <friction>
              <torsional>
                <ode/>
              </torsional>
              <ode/>
            </friction>
          </surface>
        </collision>
        <visual name='visual'>
          <cast_shadows>0</cast_shadows>
          <geometry>
            <box>
              <size>0.1 0.001 0.1</size>
            </box>
          </geometry>
          <material>
            <script>
              <uri>model://Tag0/materials/scripts</uri>
              <uri>model://Tag0/materials/textures</uri>
              <name>vrc/Tag0</name>
            </script>
          </material>
        </visual>
        <self_collide>0</self_collide>
        <enable_wind>0</enable_wind>
        <kinematic>0</kinematic>
      </link>
      <pose frame=''>0.104488 -0.735329 0 0 -0 0</pose>
    </model>
    <state world_name='default'>
      <sim_time>32 974000000</sim_time>
      <real_time>33 738984626</real_time>
      <wall_time>1567741696 352064351</wall_time>
      <iterations>32974</iterations>
      <model name='Heava'>
        <pose frame=''>0 -1 0 0 -0 0</pose>
        <scale>1 1 1</scale>
        <link name='cylinder'>
          <pose frame=''>0 -1 0 0 -0 0</pose>
          <velocity>0 0 0 0 -0 0</velocity>
          <acceleration>0 0 0 0 -0 0</acceleration>
          <wrench>0 0 0 0 -0 0</wrench>
        </link>
      </model>
      <model name='Tag0'>
        <pose frame=''>0 -0.9 0.8 0 -0 0</pose>
        <scale>1 1 1</scale>
        <link name='link'>
          <pose frame=''>0 -0.9 0.9 0 -0 0</pose>
          <velocity>0 0 0 0 -0 0</velocity>
          <acceleration>0 0 0 0 -0 0</acceleration>
          <wrench>0 0 0 0 -0 0</wrench>
        </link>
      </model>
      <model name='arm'>
        <pose frame=''>0 -3e-06 4e-06 -5e-05 -1.9e-05 2e-06</pose>
        <scale>1 1 1</scale>
        <link name='base_link'>
          <pose frame=''>0 -3e-06 4e-06 -5e-05 -1.9e-05 2e-06</pose>
          <velocity>4.7e-05 1.6e-05 0.000493 0.023319 -0.016407 0.00043</velocity>
          <acceleration>-0.291796 -0.962493 1.0764 1.83803 0.805166 -2.33764</acceleration>
          <wrench>-0.243413 -0.802902 0.897921 0 -0 0</wrench>
        </link>
        <link name='foreArm_Link'>
          <pose frame=''>-4.3e-05 -0.121682 0.529946 0.042727 -1.57034 -1.61381</pose>
          <velocity>0.000134 -0.000346 0.00042 -0.001027 0.000839 0.002366</velocity>
          <acceleration>-0.035385 0.191753 0.674367 -0.112366 -0.067168 -1.35185</acceleration>
          <wrench>-0.11677 0.632785 2.22541 0 -0 0</wrench>
        </link>
        <link name='shoulder_Link'>
          <pose frame=''>-1e-06 9e-06 0.121999 -0.000403 -7e-06 3.14132</pose>
          <velocity>-0.001053 -0.000661 0.000391 -0.000929 0.000539 0.001762</velocity>
          <acceleration>-1.28161 -1.82154 0.857343 -1.82292 0.159165 1.96594</acceleration>
          <wrench>-6.47215 -9.19878 4.32958 0 -0 0</wrench>
        </link>
        <link name='upperArm_Link'>
          <pose frame=''>-3.3e-05 -0.121492 0.121946 -3.09929 -1.57034 -1.61338</pose>
          <velocity>-0.000389 -0.000603 0.000388 -0.001024 0.001137 0.002277</velocity>
          <acceleration>-0.304553 -0.901825 0.800934 2.9732 -1.09867 -2.39015</acceleration>
          <wrench>-3.62418 -10.7317 9.53112 0 -0 0</wrench>
        </link>
        <link name='wrist1_Link'>
          <pose frame=''>-5e-05 -0.121855 0.905946 1.57125 -2.4e-05 -0.000283</pose>
          <velocity>0.000419 2.6e-05 0.000414 -0.001635 0.000649 0.001777</velocity>
          <acceleration>0.182963 0.076348 0.915966 2.56412 0.457714 -2.50019</acceleration>
          <wrench>0.2964 0.123685 1.48386 0 -0 0</wrench>
        </link>
        <link name='wrist2_Link'>
          <pose frame=''>-5.3e-05 -0.121903 1.00845 0.000492 -2.1e-05 -0.000304</pose>
          <velocity>0.000427 0.000108 0.000384 0.000831 -0.000146 0.000377</velocity>
          <acceleration>0.239934 0.302048 0.873591 0.636715 0.315734 0.872411</acceleration>
          <wrench>0.388693 0.489317 1.41522 0 -0 0</wrench>
        </link>
        <link name='wrist3_Link'>
          <pose frame=''>-8.2e-05 -0.215904 1.0084 1.57133 -3.8e-05 -0.000305</pose>
          <velocity>0.000418 9e-05 0.000209 0.002929 0.002025 -0.000603</velocity>
          <acceleration>0.273361 0.028981 0.501029 -1.84691 -0.177901 -0.659578</acceleration>
          <wrench>0.426717 0.04524 0.782107 0 -0 0</wrench>
        </link>
      </model>
      <model name='ground_plane'>
        <pose frame=''>0 0 0 0 -0 0</pose>
        <scale>1 1 1</scale>
        <link name='link'>
          <pose frame=''>0 0 0 0 -0 0</pose>
          <velocity>0 0 0 0 -0 0</velocity>
          <acceleration>0 0 0 0 -0 0</acceleration>
          <wrench>0 0 0 0 -0 0</wrench>
        </link>
      </model>
      <light name='sun'>
        <pose frame=''>0 0 10 0 -0 0</pose>
      </light>
    </state>
    <gui fullscreen='0'>
      <camera name='user_camera'>
        <pose frame=''>3.65451 -1.00074 1.17433 0 0.279643 3.09219</pose>
        <view_controller>orbit</view_controller>
        <projection_type>perspective</projection_type>
      </camera>
    </gui>
  </world>
</sdf>
