<sdf version='1.6'>
  <world name='default'>
    <light name='sun' type='directional'>
      <cast_shadows>1</cast_shadows>
      <pose frame=''>0 0 10 0 -0 0</pose>
      <diffuse>0.8 0.8 0.8 1</diffuse>
      <specular>0.2 0.2 0.2 1</specular>
      <attenuation>
        <range>1000</range>
        <constant>0.9</constant>
        <linear>0.01</linear>
        <quadratic>0.001</quadratic>
      </attenuation>
      <direction>-0.5 0.1 -0.9</direction>
    </light>
    <model name='ground_plane'>
      <static>1</static>
      <link name='link'>
        <collision name='collision'>
          <geometry>
            <plane>
              <normal>0 0 1</normal>
              <size>100 100</size>
            </plane>
          </geometry>
          <surface>
            <friction>
              <ode>
                <mu>100</mu>
                <mu2>50</mu2>
              </ode>
              <torsional>
                <ode/>
              </torsional>
            </friction>
            <contact>
              <ode/>
            </contact>
            <bounce/>
          </surface>
          <max_contacts>10</max_contacts>
        </collision>
        <visual name='visual'>
          <cast_shadows>0</cast_shadows>
          <geometry>
            <plane>
              <normal>0 0 1</normal>
              <size>100 100</size>
            </plane>
          </geometry>
          <material>
            <script>
              <uri>file://media/materials/scripts/gazebo.material</uri>
              <name>Gazebo/Grey</name>
            </script>
          </material>
        </visual>
        <self_collide>0</self_collide>
        <enable_wind>0</enable_wind>
        <kinematic>0</kinematic>
      </link>
    </model>
    <gravity>0 0 -9.8</gravity>
    <magnetic_field>6e-06 2.3e-05 -4.2e-05</magnetic_field>
    <atmosphere type='adiabatic'/>
    <physics name='default_physics' default='0' type='ode'>
      <max_step_size>0.001</max_step_size>
      <real_time_factor>1</real_time_factor>
      <real_time_update_rate>1000</real_time_update_rate>
    </physics>
    <scene>
      <ambient>0.4 0.4 0.4 1</ambient>
      <background>0.7 0.7 0.7 1</background>
      <shadows>1</shadows>
    </scene>
    <wind/>
    <spherical_coordinates>
      <surface_model>EARTH_WGS84</surface_model>
      <latitude_deg>0</latitude_deg>
      <longitude_deg>0</longitude_deg>
      <elevation>0</elevation>
      <heading_deg>0</heading_deg>
    </spherical_coordinates>
    <model name='arm'>
      <link name='base_link'>
        <pose frame=''>0 0 0 0 -0 0</pose>
        <inertial>
          <pose frame=''>-0 0.001538 0.020951 0 -0 0</pose>
          <mass>0.83419</mass>
          <inertia>
            <ixx>0.0014414</ixx>
            <ixy>7.8809e-15</ixy>
            <ixz>8.5328e-16</ixz>
            <iyy>0.0013542</iyy>
            <iyz>-1.4364e-05</iyz>
            <izz>0.0024659</izz>
          </inertia>
        </inertial>
        <collision name='base_link_collision'>
          <pose frame=''>0 0 0 0 -0 0</pose>
          <geometry>
            <mesh>
              <scale>1 1 1</scale>
              <uri>/home/xcy/WorkSpace/src/aubo_robot_realsense/aubo_description/meshes/aubo_i5/collision/base_link.STL</uri>
            </mesh>
          </geometry>
          <max_contacts>10</max_contacts>
          <surface>
            <contact>
              <ode/>
            </contact>
            <bounce/>
            <friction>
              <torsional>
                <ode/>
              </torsional>
              <ode/>
            </friction>
          </surface>
        </collision>
        <visual name='base_link_visual'>
          <pose frame=''>0 0 0 0 -0 0</pose>
          <geometry>
            <mesh>
              <scale>1 1 1</scale>
              <uri>/home/xcy/WorkSpace/src/aubo_robot_realsense/aubo_description/meshes/aubo_i5/visual/base_link.DAE</uri>
            </mesh>
          </geometry>
        </visual>
        <self_collide>0</self_collide>
        <enable_wind>0</enable_wind>
        <kinematic>0</kinematic>
      </link>
      <joint name='world_joint' type='fixed'>
        <child>base_link</child>
        <parent>world</parent>
      </joint>
      <link name='shoulder_Link'>
        <pose frame=''>0 0 0.122 0 -0 -3.14159</pose>
        <inertial>
          <pose frame=''>0 0.006 -0.002 0 -0 0</pose>
          <mass>5.05</mass>
          <inertia>
            <ixx>0.0148</ixx>
            <ixy>0</ixy>
            <ixz>0</ixz>
            <iyy>0.0143</iyy>
            <iyz>-0</iyz>
            <izz>0.0095</izz>
          </inertia>
        </inertial>
        <collision name='shoulder_Link_collision'>
          <pose frame=''>0 0 0 0 -0 0</pose>
          <geometry>
            <mesh>
              <scale>1 1 1</scale>
              <uri>/home/xcy/WorkSpace/src/aubo_robot_realsense/aubo_description/meshes/aubo_i5/collision/shoulder_Link.STL</uri>
            </mesh>
          </geometry>
          <max_contacts>10</max_contacts>
          <surface>
            <contact>
              <ode/>
            </contact>
            <bounce/>
            <friction>
              <torsional>
                <ode/>
              </torsional>
              <ode/>
            </friction>
          </surface>
        </collision>
        <visual name='shoulder_Link_visual'>
          <pose frame=''>0 0 0 0 -0 0</pose>
          <geometry>
            <mesh>
              <scale>1 1 1</scale>
              <uri>/home/xcy/WorkSpace/src/aubo_robot_realsense/aubo_description/meshes/aubo_i5/visual/shoulder_Link.DAE</uri>
            </mesh>
          </geometry>
        </visual>
        <self_collide>0</self_collide>
        <enable_wind>0</enable_wind>
        <kinematic>0</kinematic>
      </link>
      <joint name='shoulder_joint' type='revolute'>
        <child>shoulder_Link</child>
        <parent>base_link</parent>
        <axis>
          <xyz>0 0 1</xyz>
          <limit>
            <lower>-3.05</lower>
            <upper>3.05</upper>
            <effort>300</effort>
            <velocity>100</velocity>
          </limit>
          <dynamics>
            <spring_reference>0</spring_reference>
            <spring_stiffness>0</spring_stiffness>
          </dynamics>
          <use_parent_model_frame>1</use_parent_model_frame>
        </axis>
      </joint>
      <link name='upperArm_Link'>
        <pose frame=''>1e-06 -0.1215 0.122 1.57079 -1.57079 7e-06</pose>
        <inertial>
          <pose frame=''>0.304 0 -0.03 0 -0 0</pose>
          <mass>11.9</mass>
          <inertia>
            <ixx>0.0305</ixx>
            <ixy>0</ixy>
            <ixz>0</ixz>
            <iyy>0.4505</iyy>
            <iyz>0</iyz>
            <izz>0.0095</izz>
          </inertia>
        </inertial>
        <collision name='upperArm_Link_collision'>
          <pose frame=''>0 0 0 0 -0 0</pose>
          <geometry>
            <mesh>
              <scale>1 1 1</scale>
              <uri>/home/xcy/WorkSpace/src/aubo_robot_realsense/aubo_description/meshes/aubo_i5/collision/upperArm_Link.STL</uri>
            </mesh>
          </geometry>
          <max_contacts>10</max_contacts>
          <surface>
            <contact>
              <ode/>
            </contact>
            <bounce/>
            <friction>
              <torsional>
                <ode/>
              </torsional>
              <ode/>
            </friction>
          </surface>
        </collision>
        <visual name='upperArm_Link_visual'>
          <pose frame=''>0 0 0 0 -0 0</pose>
          <geometry>
            <mesh>
              <scale>1 1 1</scale>
              <uri>/home/xcy/WorkSpace/src/aubo_robot_realsense/aubo_description/meshes/aubo_i5/visual/upperArm_Link.DAE</uri>
            </mesh>
          </geometry>
        </visual>
        <self_collide>0</self_collide>
        <enable_wind>0</enable_wind>
        <kinematic>0</kinematic>
      </link>
      <joint name='upperArm_joint' type='revolute'>
        <child>upperArm_Link</child>
        <parent>shoulder_Link</parent>
        <axis>
          <xyz>4e-06 -1 0</xyz>
          <limit>
            <lower>-3.05</lower>
            <upper>3.05</upper>
            <effort>300</effort>
            <velocity>100</velocity>
          </limit>
          <dynamics>
            <spring_reference>0</spring_reference>
            <spring_stiffness>0</spring_stiffness>
          </dynamics>
          <use_parent_model_frame>1</use_parent_model_frame>
        </axis>
      </joint>
      <link name='foreArm_Link'>
        <pose frame=''>2e-06 -0.1215 0.53 -1.57081 -1.57079 7e-06</pose>
        <inertial>
          <pose frame=''>0.415 0 0.0992 0 -0 0</pose>
          <mass>3.3</mass>
          <inertia>
            <ixx>0.0033</ixx>
            <ixy>0</ixy>
            <ixz>0.0009</ixz>
            <iyy>0.0575</iyy>
            <iyz>0</iyz>
            <izz>0.0565</izz>
          </inertia>
        </inertial>
        <collision name='foreArm_Link_collision'>
          <pose frame=''>0 0 0 0 -0 0</pose>
          <geometry>
            <mesh>
              <scale>1 1 1</scale>
              <uri>/home/xcy/WorkSpace/src/aubo_robot_realsense/aubo_description/meshes/aubo_i5/collision/foreArm_Link.STL</uri>
            </mesh>
          </geometry>
          <max_contacts>10</max_contacts>
          <surface>
            <contact>
              <ode/>
            </contact>
            <bounce/>
            <friction>
              <torsional>
                <ode/>
              </torsional>
              <ode/>
            </friction>
          </surface>
        </collision>
        <visual name='foreArm_Link_visual'>
          <pose frame=''>0 0 0 0 -0 0</pose>
          <geometry>
            <mesh>
              <scale>1 1 1</scale>
              <uri>/home/xcy/WorkSpace/src/aubo_robot_realsense/aubo_description/meshes/aubo_i5/visual/foreArm_Link.DAE</uri>
            </mesh>
          </geometry>
        </visual>
        <self_collide>0</self_collide>
        <enable_wind>0</enable_wind>
        <kinematic>0</kinematic>
      </link>
      <joint name='foreArm_joint' type='revolute'>
        <child>foreArm_Link</child>
        <parent>upperArm_Link</parent>
        <axis>
          <xyz>4e-06 1 -0</xyz>
          <limit>
            <lower>-3.05</lower>
            <upper>3.05</upper>
            <effort>300</effort>
            <velocity>100</velocity>
          </limit>
          <dynamics>
            <spring_reference>0</spring_reference>
            <spring_stiffness>0</spring_stiffness>
          </dynamics>
          <use_parent_model_frame>1</use_parent_model_frame>
        </axis>
      </joint>
      <link name='wrist1_Link'>
        <pose frame=''>4e-06 -0.1215 0.906 1.5708 7e-06 -4e-06</pose>
        <inertial>
          <pose frame=''>0 0.0028 -0.003 0 -0 0</pose>
          <mass>1.62</mass>
          <inertia>
            <ixx>0.0023</ixx>
            <ixy>0</ixy>
            <ixz>0</ixz>
            <iyy>0.0013</iyy>
            <iyz>0</iyz>
            <izz>0.0022</izz>
          </inertia>
        </inertial>
        <collision name='wrist1_Link_collision'>
          <pose frame=''>0 0 0 0 -0 0</pose>
          <geometry>
            <mesh>
              <scale>1 1 1</scale>
              <uri>/home/xcy/WorkSpace/src/aubo_robot_realsense/aubo_description/meshes/aubo_i5/collision/wrist1_Link.STL</uri>
            </mesh>
          </geometry>
          <max_contacts>10</max_contacts>
          <surface>
            <contact>
              <ode/>
            </contact>
            <bounce/>
            <friction>
              <torsional>
                <ode/>
              </torsional>
              <ode/>
            </friction>
          </surface>
        </collision>
        <visual name='wrist1_Link_visual'>
          <pose frame=''>0 0 0 0 -0 0</pose>
          <geometry>
            <mesh>
              <scale>1 1 1</scale>
              <uri>/home/xcy/WorkSpace/src/aubo_robot_realsense/aubo_description/meshes/aubo_i5/visual/wrist1_Link.DAE</uri>
            </mesh>
          </geometry>
        </visual>
        <self_collide>0</self_collide>
        <enable_wind>0</enable_wind>
        <kinematic>0</kinematic>
      </link>
      <joint name='wrist1_joint' type='revolute'>
        <child>wrist1_Link</child>
        <parent>foreArm_Link</parent>
        <axis>
          <xyz>-4e-06 -1 -7e-06</xyz>
          <limit>
            <lower>-3.05</lower>
            <upper>3.05</upper>
            <effort>300</effort>
            <velocity>100</velocity>
          </limit>
          <dynamics>
            <spring_reference>0</spring_reference>
            <spring_stiffness>0</spring_stiffness>
          </dynamics>
          <use_parent_model_frame>1</use_parent_model_frame>
        </axis>
      </joint>
      <link name='wrist2_Link'>
        <pose frame=''>5e-06 -0.121501 1.0085 4e-06 7e-06 -4e-06</pose>
        <inertial>
          <pose frame=''>0 -0.0028 -0.003 0 -0 0</pose>
          <mass>1.62</mass>
          <inertia>
            <ixx>0.0023</ixx>
            <ixy>0</ixy>
            <ixz>0</ixz>
            <iyy>0.0013</iyy>
            <iyz>0</iyz>
            <izz>0.0022</izz>
          </inertia>
        </inertial>
        <collision name='wrist2_Link_collision'>
          <pose frame=''>0 0 0 0 -0 0</pose>
          <geometry>
            <mesh>
              <scale>1 1 1</scale>
              <uri>/home/xcy/WorkSpace/src/aubo_robot_realsense/aubo_description/meshes/aubo_i5/collision/wrist2_Link.STL</uri>
            </mesh>
          </geometry>
          <max_contacts>10</max_contacts>
          <surface>
            <contact>
              <ode/>
            </contact>
            <bounce/>
            <friction>
              <torsional>
                <ode/>
              </torsional>
              <ode/>
            </friction>
          </surface>
        </collision>
        <visual name='wrist2_Link_visual'>
          <pose frame=''>0 0 0 0 -0 0</pose>
          <geometry>
            <mesh>
              <scale>1 1 1</scale>
              <uri>/home/xcy/WorkSpace/src/aubo_robot_realsense/aubo_description/meshes/aubo_i5/visual/wrist2_Link.DAE</uri>
            </mesh>
          </geometry>
        </visual>
        <self_collide>0</self_collide>
        <enable_wind>0</enable_wind>
        <kinematic>0</kinematic>
      </link>
      <joint name='wrist2_joint' type='revolute'>
        <child>wrist2_Link</child>
        <parent>wrist1_Link</parent>
        <axis>
          <xyz>7e-06 -4e-06 1</xyz>
          <limit>
            <lower>-3.05</lower>
            <upper>3.05</upper>
            <effort>300</effort>
            <velocity>100</velocity>
          </limit>
          <dynamics>
            <spring_reference>0</spring_reference>
            <spring_stiffness>0</spring_stiffness>
          </dynamics>
          <use_parent_model_frame>1</use_parent_model_frame>
        </axis>
      </joint>
      <link name='wrist3_Link'>
        <pose frame=''>4e-06 -0.215501 1.0085 1.5708 7e-06 -4e-06</pose>
        <inertial>
          <pose frame=''>0.00843 -0.010465 0.012449 0 -0 0</pose>
          <mass>0.997</mass>
          <inertia>
            <ixx>0.0147919</ixx>
            <ixy>6.71967e-05</ixy>
            <ixz>-0.000120191</ixz>
            <iyy>0.0181932</iyy>
            <iyz>0.000149201</iyz>
            <izz>0.0264301</izz>
          </inertia>
        </inertial>
        <collision name='wrist3_Link_collision'>
          <pose frame=''>0 0 0 0 -0 0</pose>
          <geometry>
            <mesh>
              <scale>1 1 1</scale>
              <uri>/home/xcy/WorkSpace/src/aubo_robot_realsense/aubo_description/meshes/aubo_i5/collision/wrist3_Link.STL</uri>
            </mesh>
          </geometry>
          <max_contacts>10</max_contacts>
          <surface>
            <contact>
              <ode/>
            </contact>
            <bounce/>
            <friction>
              <torsional>
                <ode/>
              </torsional>
              <ode/>
            </friction>
          </surface>
        </collision>
        <collision name='wrist3_Link_fixed_joint_lump__camera_mount_link_collision_1'>
          <pose frame=''>0 0 0.005 3.14159 -1.57079 1.57089</pose>
          <geometry>
            <mesh>
              <scale>1 1 1</scale>
              <uri>/home/xcy/WorkSpace/src/aubo_robot_realsense/aubo_description/meshes/CameraMountBoard.stl</uri>
            </mesh>
          </geometry>
          <surface>
            <contact>
              <ode/>
            </contact>
            <friction>
              <ode/>
              <torsional>
                <ode/>
              </torsional>
            </friction>
            <bounce/>
          </surface>
          <max_contacts>10</max_contacts>
        </collision>
        <collision name='wrist3_Link_fixed_joint_lump__camera_link_collision_2'>
          <pose frame=''>-0.002598 -0.018502 0.027748 3.14159 -1.57079 1.57089</pose>
          <geometry>
            <box>
              <size>0.02505 0.09 0.025</size>
            </box>
          </geometry>
          <surface>
            <contact>
              <ode/>
            </contact>
            <friction>
              <ode/>
              <torsional>
                <ode/>
              </torsional>
            </friction>
            <bounce/>
          </surface>
          <max_contacts>10</max_contacts>
        </collision>
        <visual name='wrist3_Link_visual'>
          <pose frame=''>0 0 0 0 -0 0</pose>
          <geometry>
            <mesh>
              <scale>1 1 1</scale>
              <uri>/home/xcy/WorkSpace/src/aubo_robot_realsense/aubo_description/meshes/aubo_i5/visual/wrist3_Link.DAE</uri>
            </mesh>
          </geometry>
        </visual>
        <visual name='wrist3_Link_fixed_joint_lump__camera_mount_link_visual_1'>
          <pose frame=''>0 0 0.005 3.14159 -1.57079 1.57089</pose>
          <geometry>
            <mesh>
              <scale>1 1 1</scale>
              <uri>/home/xcy/WorkSpace/src/aubo_robot_realsense/aubo_description/meshes/CameraMountBoard.dae</uri>
            </mesh>
          </geometry>
          <material>
            <script>
              <name>Gazebo/White</name>
              <uri>file://media/materials/scripts/gazebo.material</uri>
            </script>
          </material>
        </visual>
        <visual name='wrist3_Link_fixed_joint_lump__camera_link_visual_2'>
          <pose frame=''>-0.002598 -0.018504 0.041648 0 -9.6e-05 9.6e-05</pose>
          <geometry>
            <mesh>
              <scale>1 1 1</scale>
              <uri>/home/xcy/WorkSpace/src/aubo_robot_realsense/aubo_description/meshes/d435.dae</uri>
            </mesh>
          </geometry>
          <material>
            <script>
              <name>Gazebo/Gray</name>
              <uri>file://media/materials/scripts/gazebo.material</uri>
            </script>
          </material>
        </visual>
        <velocity_decay/>
        <velocity_decay/>
        <gravity>1</gravity>
        <velocity_decay/>
        <sensor name='camera1' type='camera'>
          <update_rate>30</update_rate>
          <camera name='realsense'>
            <horizontal_fov>1.047</horizontal_fov>
            <image>
              <width>640</width>
              <height>480</height>
              <format>RGB_INT8</format>
            </image>
            <clip>
              <near>0.1</near>
              <far>100</far>
            </clip>
            <noise>
              <type>gaussian</type>
              <mean>0</mean>
              <stddev>0.007</stddev>
            </noise>
          </camera>
          <plugin name='camera_controller' filename='libgazebo_ros_camera.so'>
            <alwaysOn>1</alwaysOn>
            <updateRate>30.0</updateRate>
            <cameraName>camera/color</cameraName>
            <imageTopicName>image_raw</imageTopicName>
            <cameraInfoTopicName>camera_info</cameraInfoTopicName>
            <frameName>camera_color_optical_frame</frameName>
            <distortionK1>0.0</distortionK1>
            <distortionK2>0.0</distortionK2>
            <distortionK3>0.0</distortionK3>
            <distortionT1>0.0</distortionT1>
            <distortionT2>0.0</distortionT2>
            <CxPrime>0.0</CxPrime>
            <Cx>324.5312805175781</Cx>
            <Cy>236.61178588867188</Cy>
            <robotNamespace>/</robotNamespace>
          </plugin>
          <pose frame=''>0.029902 -0.018499 0.026748 -1.34896 -1.56156 -0.228751</pose>
        </sensor>
        <self_collide>0</self_collide>
        <enable_wind>0</enable_wind>
        <kinematic>0</kinematic>
      </link>
      <joint name='wrist3_joint' type='revolute'>
        <child>wrist3_Link</child>
        <parent>wrist2_Link</parent>
        <axis>
          <xyz>-4e-06 -1 -7e-06</xyz>
          <limit>
            <lower>-3.05</lower>
            <upper>3.05</upper>
            <effort>300</effort>
            <velocity>100</velocity>
          </limit>
          <dynamics>
            <spring_reference>0</spring_reference>
            <spring_stiffness>0</spring_stiffness>
          </dynamics>
          <use_parent_model_frame>1</use_parent_model_frame>
        </axis>
      </joint>
      <static>0</static>
      <plugin name='gazebo_ros_control' filename='libgazebo_ros_control.so'>
        <robotNamespace>/aubo_i5</robotNamespace>
        <robotSimType>gazebo_ros_control/DefaultRobotHWSim</robotSimType>
        <legacyModeNS>1</legacyModeNS>
      </plugin>
      <pose frame=''>0 0 0 0 -0 0</pose>
    </model>
    <model name='Heava'>
      <static>1</static>
      <pose frame=''>0.03711 -0.841028 0 0 -0 0</pose>
      <link name='cylinder'>
        <pose frame=''>0 0 0 0 -0 0</pose>
        <collision name='collision'>
          <geometry>
            <cylinder>
              <radius>0.1</radius>
              <length>5</length>
            </cylinder>
          </geometry>
          <max_contacts>10</max_contacts>
          <surface>
            <contact>
              <ode/>
            </contact>
            <bounce/>
            <friction>
              <torsional>
                <ode/>
              </torsional>
              <ode/>
            </friction>
          </surface>
        </collision>
        <visual name='visual'>
          <geometry>
            <cylinder>
              <radius>0.1</radius>
              <length>5</length>
            </cylinder>
          </geometry>
          <material>
            <script>
              <uri>model://Heava/materials/scripts</uri>
              <uri>model://Heava/materials/textures</uri>
              <name>Heava/skin</name>
            </script>
          </material>
        </visual>
        <self_collide>0</self_collide>
        <enable_wind>0</enable_wind>
        <kinematic>0</kinematic>
      </link>
    </model>
    <state world_name='default'>
      <sim_time>1377 701000000</sim_time>
      <real_time>1283 521160801</real_time>
      <wall_time>1571129544 902094186</wall_time>
      <iterations>1281585</iterations>
      <model name='Heava'>
        <pose frame=''>0 -0.6 0 0 -0 0</pose>
        <scale>1 1 1</scale>
        <link name='cylinder'>
          <pose frame=''>0 -0.6 0 0 -0 0</pose>
          <velocity>0 0 0 0 -0 0</velocity>
          <acceleration>0 0 0 0 -0 0</acceleration>
          <wrench>0 0 0 0 -0 0</wrench>
        </link>
      </model>
      <model name='Tag0_0'>
        <pose frame=''>0 -0.5 0.7 0 -0 0</pose>
        <scale>1 1 1</scale>
        <link name='link'>
          <pose frame=''>0 -0.5 0.8 0 -0 0</pose>
          <velocity>0 0 0 0 -0 0</velocity>
          <acceleration>0 0 0 0 -0 0</acceleration>
          <wrench>0 0 0 0 -0 0</wrench>
        </link>
      </model>
      <model name='arm'>
        <pose frame=''>4e-06 -0 4e-06 -1.5e-05 -8.1e-05 2e-06</pose>
        <scale>1 1 1</scale>
        <link name='base_link'>
          <pose frame=''>4e-06 -0 4e-06 -1.5e-05 -8.1e-05 2e-06</pose>
          <velocity>1.9e-05 -2.8e-05 -0.000651 0.000266 -0.033695 -0.000376</velocity>
          <acceleration>-1.37295 -0.067147 -1.30037 -2.60886 1.4159 2.39085</acceleration>
          <wrench>-1.14531 -0.056013 -1.08475 0 -0 0</wrench>
        </link>
        <link name='foreArm_Link'>
          <pose frame=''>0.099375 0.070203 0.529945 1.56985 1.08089 -0.952856</pose>
          <velocity>0.001064 -0.001363 -0.000455 0.011384 0.008481 -0.000508</velocity>
          <acceleration>0.117226 -0.370626 -0.645335 -2.06872 -1.54905 -0.648558</acceleration>
          <wrench>0.386845 -1.22306 -2.12961 0 -0 0</wrench>
        </link>
        <link name='shoulder_Link'>
          <pose frame=''>-1e-05 2e-06 0.121999 -0.000386 0.000312 -0.952019</pose>
          <velocity>-0.001466 0.000353 -0.000459 -0.000571 0.001614 0.000308</velocity>
          <acceleration>-2.94313 0.711135 -0.93764 2.02531 0.005716 -1.76672</acceleration>
          <wrench>-14.8628 3.59123 -4.73508 0 -0 0</wrench>
        </link>
        <link name='upperArm_Link'>
          <pose frame=''>0.098975 0.070459 0.121948 -1.95797 -1.56964 -0.56485</pose>
          <velocity>-0.001011 -0.000261 -0.000492 0.002976 0.004473 0.000138</velocity>
          <acceleration>-0.781694 -0.251819 -0.870104 2.47092 -0.491168 0.238511</acceleration>
          <wrench>-9.30216 -2.99665 -10.3542 0 -0 0</wrench>
        </link>
        <link name='wrist1_Link'>
          <pose frame=''>0.201876 -0.074002 0.198169 1.57127 -0.301972 2.18947</pose>
          <velocity>-0.001791 0.002369 -0.002925 0.010871 0.007875 -0.001278</velocity>
          <acceleration>0.192389 -0.327704 -0.641403 -0.786822 0.237807 -2.96075</acceleration>
          <wrench>0.31167 -0.53088 -1.03907 0 -0 0</wrench>
        </link>
        <link name='wrist2_Link'>
          <pose frame=''>0.219595 -0.098807 0.29603 0.010167 -0.301829 2.15692</pose>
          <velocity>-0.000999 0.001369 -0.003279 0.009569 0.007284 -0.00229</velocity>
          <acceleration>0.25372 -0.144731 -0.51831 -1.13239 -0.71471 2.91854</acceleration>
          <wrench>0.411026 -0.234464 -0.839662 0 -0 0</wrench>
        </link>
        <link name='wrist3_Link'>
          <pose frame=''>0.297745 -0.046579 0.295116 1.58099 -0.302785 2.15691</pose>
          <velocity>-0.000876 0.00122 -0.003261 0.011071 0.006543 -0.002003</velocity>
          <acceleration>0.312638 -0.124153 -0.302788 0.217032 1.36245 0.284056</acceleration>
          <wrench>0.3117 -0.123781 -0.30188 0 -0 0</wrench>
        </link>
      </model>
      <model name='ground_plane'>
        <pose frame=''>0 0 0 0 -0 0</pose>
        <scale>1 1 1</scale>
        <link name='link'>
          <pose frame=''>0 0 0 0 -0 0</pose>
          <velocity>0 0 0 0 -0 0</velocity>
          <acceleration>0 0 0 0 -0 0</acceleration>
          <wrench>0 0 0 0 -0 0</wrench>
        </link>
      </model>
      <light name='sun'>
        <pose frame=''>0 0 10 0 -0 0</pose>
      </light>
    </state>
    <gui fullscreen='0'>
      <camera name='user_camera'>
        <pose frame=''>-2.54887 0.041456 1.68369 -0 0.483646 0.216993</pose>
        <view_controller>orbit</view_controller>
        <projection_type>perspective</projection_type>
      </camera>
    </gui>
    <model name='Tag0_0'>
      <static>1</static>
      <link name='link'>
        <pose frame=''>0 0 0.1 0 -0 0</pose>
        <collision name='collision'>
          <geometry>
            <box>
              <size>0.1 0.001 0.1</size>
            </box>
          </geometry>
          <max_contacts>10</max_contacts>
          <surface>
            <contact>
              <ode/>
            </contact>
            <bounce/>
            <friction>
              <torsional>
                <ode/>
              </torsional>
              <ode/>
            </friction>
          </surface>
        </collision>
        <visual name='visual'>
          <cast_shadows>0</cast_shadows>
          <geometry>
            <box>
              <size>0.1 0.001 0.1</size>
            </box>
          </geometry>
          <material>
            <script>
              <uri>model://Tag0/materials/scripts</uri>
              <uri>model://Tag0/materials/textures</uri>
              <name>vrc/Tag0</name>
            </script>
          </material>
        </visual>
        <self_collide>0</self_collide>
        <enable_wind>0</enable_wind>
        <kinematic>0</kinematic>
      </link>
      <pose frame=''>-0.089371 -0.367954 0 0 -0 0</pose>
    </model>
  </world>
</sdf>
